Workbook

Sheet paste-csv-here
B1: model_id | C1: model_name | D1: r-squared | E1: coeff_name | F1: coeff_value | G1: t_stat_value
B2: 1 | C2: AM Travel Time Index | D2: 0.876879 | E2: coeff_00 | F2: 0.10744387 | G2: 9.87863
B3: 1 | C3: AM Travel Time Index | D3: 0.876879 | E3: coeff_01 | F3: 0.0077043089 | G3: 0.7189019
B4: 1 | C4: AM Travel Time Index | D4: 0.876879 | E4: coeff_02 | F4: -0.24253521 | G4: -22.695643
B5: 1 | C5: AM Travel Time Index | D5: 0.876879 | E5: coeff_03 | F5: 0.034418624 | G5: 3.1006039
B6: 1 | C6: AM Travel Time Index | D6: 0.876879 | E6: coeff_04 | F6: -0.13537961 | G6: -3.892039
B7: 1 | C7: AM Travel Time Index | D7: 0.876879 | E7: coeff_05 | F7: 0.017979836 | G7: 1.6728565
B8: 1 | C8: AM Travel Time Index | D8: 0.876879 | E8: coeff_06 | F8: 0.15415132 | G8: 2.8470867
B9: 1 | C9: AM Travel Time Index | D9: 0.876879 | E9: coeff_07 | F9: -0.0076861547 | G9: -1.0780814
B10: 1 | C10: AM Travel Time Index | D10: 0.876879 | E10: coeff_08 | F10: -0.23969441 | G10: -2.2071281
B11: 1 | C11: AM Travel Time Index | D11: 0.876879 | E11: coeff_09 | F11: 0.0016637893 | G11: 0.077234538
B12: 1 | C12: AM Travel Time Index | D12: 0.876879 | E12: coeff_10 | F12: 0.00057936626
B13: 1 | C13: AM Travel Time Index | D13: 0.876879 | E13: coeff_11 | F13: -0.00057936626
B14: 1 | C14: AM Travel Time Index | D14: 0.876879 | E14: coeff_12 | F14: -0.0071338571
B15: 1 | C15: AM Travel Time Index | D15: 0.876879 | E15: coeff_13 | F15: 0.013379736
B16: 1 | C16: AM Travel Time Index | D16: 0.876879 | E16: coeff_14 | F16: -0.0062458789
B17: 1 | C17: AM Travel Time Index | D17: 0.876879 | E17: intercept | F17: 1.4638021
B18: 2 | C18: Auto Accessibility Peak | D18: 0.8261483 | E18: coeff_00 | F18: -2808.9309 | G18: -2.662328
B19: 2 | C19: Auto Accessibility Peak | D19: 0.8261483 | E19: coeff_01 | F19: 3886.2748 | G19: 3.7383062
B20: 2 | C20: Auto Accessibility Peak | D20: 0.8261483 | E20: coeff_02 | F20: 20661.644 | G20: 19.931409
B21: 2 | C21: Auto Accessibility Peak | D21: 0.8261483 | E21: coeff_03 | F21: -3437.1535 | G21: -3.1919578
B22: 2 | C22: Auto Accessibility Peak | D22: 0.8261483 | E22: coeff_04 | F22: 15707.138 | G22: 4.6550721
B23: 2 | C23: Auto Accessibility Peak | D23: 0.8261483 | E23: coeff_05 | F23: -1262.0155 | G23: -1.2104395
B24: 2 | C24: Auto Accessibility Peak | D24: 0.8261483 | E24: coeff_06 | F24: -14313.057 | G24: -2.7251553
B25: 2 | C25: Auto Accessibility Peak | D25: 0.8261483 | E25: coeff_07 | F25: 1353.2328 | G25: 1.9566825
B26: 2 | C26: Auto Accessibility Peak | D26: 0.8261483 | E26: coeff_08 | F26: 7370.8689 | G26: 0.6996708
B27: 2 | C27: Auto Accessibility Peak | D27: 0.8261483 | E27: coeff_09 | F27: -1147.8387 | G27: -0.54928727
B28: 2 | C28: Auto Accessibility Peak | D28: 0.8261483 | E28: coeff_10 | F28: -194.54314
B29: 2 | C29: Auto Accessibility Peak | D29: 0.8261483 | E29: coeff_11 | F29: 194.54314
B30: 2 | C30: Auto Accessibility Peak | D30: 0.8261483 | E30: coeff_12 | F30: 295.89862
B31: 2 | C31: Auto Accessibility Peak | D31: 0.8261483 | E31: coeff_13 | F31: -689.72722
B32: 2 | C32: Auto Accessibility Peak | D32: 0.8261483 | E32: coeff_14 | F32: 393.8286
B33: 2 | C33: Auto Accessibility Peak | D33: 0.8261483 | E33: intercept | F33: 36805.653
B34: 3 | C34: Auto Accessibility Peak within 30 Minutes | D34: 0.85480291 | E34: coeff_00 | F34: -14890.184 | G34: -2.839859
B35: 3 | C35: Auto Accessibility Peak within 30 Minutes | D35: 0.85480291 | E35: coeff_01 | F35: 18983.453 | G35: 3.6744538
B36: 3 | C36: Auto Accessibility Peak within 30 Minutes | D36: 0.85480291 | E36: coeff_02 | F36: 114829.42 | G36: 22.289612
B37: 3 | C37: Auto Accessibility Peak within 30 Minutes | D37: 0.85480291 | E37: coeff_03 | F37: -17980.276 | G37: -3.3599343
B38: 3 | C38: Auto Accessibility Peak within 30 Minutes | D38: 0.85480291 | E38: coeff_04 | F38: 86162.314 | G38: 5.1383408
B39: 3 | C39: Auto Accessibility Peak within 30 Minutes | D39: 0.85480291 | E39: coeff_05 | F39: -6314.7482 | G39: -1.2187388
B40: 3 | C40: Auto Accessibility Peak within 30 Minutes | D40: 0.85480291 | E40: coeff_06 | F40: -79028.229 | G40: -3.0277313
...

Sheet coeff_names
A1: coeff_name | B1: label
A2: coeff_00 | B2: Automated vehicle adoption rate
A3: coeff_01 | B3: Electric vehicle adoption rate
A4: coeff_02 | B4: E-commerce level
A5: coeff_03 | B5: Household and employment distribution
A6: coeff_04 | B6: Household and employment growth
A7: coeff_05 | B7: Heavy and medium truck travel
A8: coeff_06 | B8: Incentives for special populations
A9: coeff_07 | B9: Road user fee
A10: coeff_08 | B10: Roadway capacity improvements
A11: coeff_09 | B11: Teleworking
A12: coeff_10 | B12: Transit headways
... A16: coeff_14 | B16: Unknown

Sheet model-01
A1: model | C1: =+VLOOKUP(A2,'paste-csv-here'!B:F,2,FALSE) -> AM Travel Time Index
A2: 1 | C2: =+_xlfn.CONCAT("R-squared = ",TEXT(VLOOKUP(A2,'paste-csv-here'!B:F,3,FALSE),"0.000")) -> R-squared = 0.877
C4: Variable | D4: Coefficient | E4: t-statistic
A5: intercept | C5: Intercept | D5: =+SUMIFS('paste-csv-here'!F:F,'paste-csv-here'!E:E,A5,'paste-csv-here'!B:B,A$2) -> 1.4638021 | E5: =+SUMIFS('paste-csv-here'!G:G,'paste-csv-here'!E:E,A5,'paste-csv-here'!B:B,A$2) -> 0
A6: coeff_00 | C6: =+VLOOKUP(A6,coeff_names!A:B,2,FALSE) -> Automated vehicle adoption rate | D6: =+SUMIFS('paste-csv-here'!F:F,'paste-csv-here'!E:E,A6,'paste-csv-here'!B:B,A$2) -> 0.10744387 | E6: =+SUMIFS('paste-csv-here'!G:G,'paste-csv-here'!E:E,A6,'paste-csv-here'!B:B,A$2) -> 9.87863
A7: coeff_01 | C7: =+VLOOKUP(A7,coeff_names!A:B,2,FALSE) -> Electric vehicle adoption rate | D7: =+SUMIFS('paste-csv-here'!F:F,'paste-csv-here'!E:E,A7,'paste-csv-here'!B:B,A$2) -> 0.0077043089 | E7: =+SUMIFS('paste-csv-here'!G:G,'paste-csv-here'!E:E,A7,'paste-csv-here'!B:B,A$2) -> 0.7189019
A8: coeff_02 | C8: =+VLOOKUP(A8,coeff_names!A:B,2,FALSE) -> E-commerce level | D8: =+SUMIFS('paste-csv-here'!F:F,'paste-csv-here'!E:E,A8,'paste-csv-here'!B:B,A$2) -> -0.24253521 | E8: =+SUMIFS('paste-csv-here'!G:G,'paste-csv-here'!E:E,A8,'paste-csv-here'!B:B,A$2) -> -22.695643
A9: coeff_03 | C9: =+VLOOKUP(A9,coeff_names!A:B,2,FALSE) -> Household and employment distribution | D9: =+SUMIFS('paste-csv-here'!F:F,'paste-csv-here'!E:E,A9,'paste-csv-here'!B:B,A$2) -> 0.034418624 | E9: =+SUMIFS('paste-csv-here'!G:G,'paste-csv-here'!E:E,A9,'paste-csv-here'!B:B,A$2) -> 3.1006039
A10: coeff_04 | C10: =+VLOOKUP(A10,coeff_names!A:B,2,FALSE) -> Household and employment growth | D10: =+SUMIFS('paste-csv-here'!F:F,'paste-csv-here'!E:E,A10,'paste-csv-here'!B:B,A$2) -> -0.13537961 | E10: =+SUMIFS('paste-csv-here'!G:G,'paste-csv-here'!E:E,A10,'paste-csv-here'!B:B,A$2) -> -3.892039
A11: coeff_05 | C11: =+VLOOKUP(A11,coeff_names!A:B,2,FALSE) -> Heavy and medium truck travel | D11: =+SUMIFS('paste-csv-here'!F:F,'paste-csv-here'!E:E,A11,'paste-csv-here'!B:B,A$2) -> 0.017979836 | E11: =+SUMIFS('paste-csv-here'!G:G,'paste-csv-here'!E:E,A11,'paste-csv-here'!B:B,A$2) -> 1.6728565
A12: coeff_06 | C12: =+VLOOKUP(A12,coeff_names!A:B,2,FALSE) -> Incentives for special populations | D12: =+SUMIFS('paste-csv-here'!F:F,'paste-csv-here'!E:E,A12,'paste-csv-here'!B:B,A$2) -> 0.15415132 | E12: =+SUMIFS('paste-csv-here'!G:G,'paste-csv-here'!E:E,A12,'paste-csv-here'!B:B,A$2) -> 2.8470867
A13: coeff_07 | C13: =+VLOOKUP(A13,coeff_names!A:B,2,FALSE) -> Road user fee | D13: =+SUMIFS('paste-csv-here'!F:F,'paste-csv-here'!E:E,A13,'paste-csv-here'!B:B,A$2) -> -0.0076861547 | E13: =+SUMIFS('paste-csv-here'!G:G,'paste-csv-here'!E:E,A13,'paste-csv-here'!B:B,A$2) -> -1.0780814
A14: coeff_08 | C14: =+VLOOKUP(A14,coeff_names!A:B,2,FALSE) -> Roadway capacity improvements | D14: =+SUMIFS('paste-csv-here'!F:F,'paste-csv-here'!E:E,A14,'paste-csv-here'!B:B,A$2) -> -0.23969441 | E14: =+SUMIFS('paste-csv-here'!G:G,'paste-csv-here'!E:E,A14,'paste-csv-here'!B:B,A$2) -> -2.2071281
A15: coeff_09 | C15: =+VLOOKUP(A15,coeff_names!A:B,2,FALSE) -> Teleworking | D15: =+SUMIFS('paste-csv-here'!F:F,'paste-csv-here'!E:E,A15,'paste-csv-here'!B:B,A$2) -> 0.0016637893 | E15: =+SUMIFS('paste-csv-here'!G:G,'paste-csv-here'!E:E,A15,'paste-csv-here'!B:B,A$2) -> 0.077234538
A16: coeff_10 | C16: =+VLOOKUP(A16,coeff_names!A:B,2,FALSE) -> Transit headways | D16: =+SUMIFS('paste-csv-here'!F:F,'paste-csv-here'!E:E,A16,'paste-csv-here'!B:B,A$2) -> 0.00057936626 | E16: =+SUMIFS('paste-csv-here'!G:G,'paste-csv-here'!E:E,A16,'paste-csv-here'!B:B,A$2) -> 0
A17: coeff_11 | C17: =+VLOOKUP(A17,coeff_names!A:B,2,FALSE) -> Transit service expansion | D17: =+SUMIFS('paste-csv-here'!F:F,'paste-csv-here'!E:E,A17,'paste-csv-here'!B:B,A$2) -> -0.00057936626 | E17: =+SUMIFS('paste-csv-here'!G:G,'paste-csv-here'!E:E,A17,'paste-csv-here'!B:B,A$2) -> 0
... A20: coeff_14 | C20: =+VLOOKUP(A20,coeff_names!A:B,2,FALSE) -> Unknown | D20: =+SUMIFS('paste-csv-here'!F:F,'paste-csv-here'!E:E,A20,'paste-csv-here'!B:B,A$2) -> -0.0062458789 | E20: =+SUMIFS('paste-csv-here'!G:G,'paste-csv-here'!E:E,A20,'paste-csv-here'!B:B,A$2) -> 0
